Workbook

Sheet 资产负债表
B1: 资产负债表（适用执行民间非营利组织会计制度的组织）
I2: 会民非01表 单位:元
B3: 纳税人识别号 | C3: 52310106MJ50512445 | F3: 纳税人名称 | G3: 上海静安千千结婚恋服务中心
B4: 所属期起 | F4: 所属期止
B5: 资产 | C5: 行次 | D5: 年初数 | E5: 期末数 | F5: 负债和净资产 | G5: 行次 | H5: 年初数 | I5: 期末数
B6: 流动资产： | F6: 流动负债：
B7: 货币资金 | C7: 1 | D7: 0 | E7: 0 | F7: 短期借款 | G7: 61 | H7: 0 | I7: 0
B8: 短期投资 | C8: 2 | D8: 0 | E8: 0 | F8: 应付款项 | G8: 62 | H8: 0 | I8: 0
B9: 应收款项 | C9: 3 | D9: 0 | E9: 0 | F9: 应付工资 | G9: 63 | H9: 0 | I9: 0
B10: 预付账款 | C10: 4 | D10: 0 | E10: 0 | F10: 应交税金 | G10: 65 | H10: 0 | I10: 0
B11: 存货 | C11: 8 | D11: 0 | E11: 0 | F11: 预收账款 | G11: 66 | H11: 0 | I11: 0
B12: 待摊费用 | C12: 9 | D12: 0 | E12: 0 | F12: 预提费用 | G12: 71 | H12: 0 | I12: 0
B13: 一年内到期的长期债权投资 | C13: 15 | D13: 0 | E13: 0 | F13: 预计负债 | G13: 72 | H13: 0 | I13: 0
B14: 其他流动资产 | C14: 18 | D14: 0 | E14: 0 | F14: 一年内到期的长期负债 | G14: 74 | H14: 0 | I14: 0
B15: 流动资产合计 | C15: 20 | D15: =ROUND((D7+D8+D9+D10+D11+D12+D13+D14),2) -> 0 | E15: =ROUND((E7+E8+E9+E10+E11+E12+E13+E14),2) -> 0 | F15: 其他流动负债 | G15: 78 | H15: 0 | I15: 0
F16: 流动负债合计 | G16: 80 | H16: =ROUND((H7+H8+H9+H10+H11+H12+H13+H14+H15),2) -> 0 | I16: =ROUND((I7+I8+I9+I10+I11+I12+I13+I14+I15),2) -> 0
B17: 长期投资：
B18: 长期股权投资 | C18: 21 | D18: 0 | E18: 0 | F18: 长期负债：
B19: 长期债权投资 | C19: 24 | D19: 0 | E19: 0 | F19: 长期借款 | G19: 81 | H19: 0 | I19: 0
B20: 长期投资合计 | C20: 30 | D20: =ROUND((D18+D19),2) -> 0 | E20: =ROUND((E18+E19),2) -> 0 | F20: 长期应付款 | G20: 84 | H20: 0 | I20: 0
F21: 其他长期负债 | G21: 88 | H21: 0 | I21: 0
B22: 固定资产： | F22: 长期负债合计 | G22: 90 | H22: =ROUND((H19+H20+H21),2) -> 0 | I22: =ROUND((I19+I20+I21),2) -> 0
B23: 固定资产原价 | C23: 31 | D23: 0 | E23: 0
B24: 减：累计折旧 | C24: 32 | D24: 0 | E24: 0 | F24: 受托代理负债：
B25: 固定资产净值 | C25: 33 | D25: =ROUND(资产负债表!D23-资产负债表!D24,2) -> 0 | E25: =ROUND(资产负债表!E23-资产负债表!E24,2) -> 0 | F25: 受托代理负债 | G25: 91 | H25: 0 | I25: 0
B26: 在建工程 | C26: 34 | D26: 0 | E26: 0
B27: 文物文化资产 | C27: 35 | D27: 0 | E27: 0 | F27: 负债合计 | G27: 100 | H27: =ROUND(资产负债表!H16+资产负债表!H22+资产负债表!H25,2) -> 0 | I27: =ROUND(资产负债表!I16+资产负债表!I22+资产负债表!I25,2) -> 0
B28: 固定资产清理 | C28: 38 | D28: 0 | E28: 0
B29: 固定资产合计 | C29: 40 | D29: =ROUND((D25+D26+D27+D28),2) -> 0 | E29: =ROUND((E25+E26+E27+E28),2) -> 0
B30: 无形资产：
B31: 无形资产 | C31: 41 | D31: 0 | E31: 0 | F31: 净资产：
F32: 非限定性净资产 | G32: 101 | H32: 0 | I32: 0
B33: 受托代理资产： | F33: 限定性净资产 | G33: 105 | H33: 0 | I33: 0
B34: 受托代理资产 | C34: 51 | D34: 0 | E34: 0 | F34: 净资产合计 | G34: 110 | H34: =ROUND(资产负债表!H32+资产负债表!H33,2) -> 0 | I34: =ROUND(资产负债表!I32+资产负债表!I33,2) -> 0
B35: 资产总计 | C35: 60 | D35: =ROUND(资产负债表!D15+资产负债表!D20+资产负债表!D29+资产负债表!D31+资产负债表!D34,2) -> 0 | E35: =ROUND(资产负债表!E15+资产负债表!E20+资产负债表!E29+资产负债表!E31+资产负债表!E34,2) -> 0 | F35: 负债和净资产总计 | G35: 120 | H35: =ROUND(资产负债表!H27+资产负债表!H34,2) -> 0 | I35: =ROUND(资产负债表!I27+资产负债表!I34,2) -> 0
B36: =IF(ROUND(D35,2)=ROUND(H35,2),IF(ROUND(E35,2)=ROUND(I35,2),"","提示：资产总计期末数与负债和净资产总计期末数不等"),"提示：资产总计年初数与负债和资产总计年初数不等")

Sheet 业务活动表
B1: 业务活动表（适用执行民间非营利组织会计制度的组织）
I2: 会民非02表 单位:元
B3: 纳税人识别号 | C3: =IF(资产负债表!C3="","",资产负债表!C3) -> 52310106MJ50512445 | F3: 纳税人名称 | G3: =IF(资产负债表!G3="","",资产负债表!G3) -> 上海静安千千结婚恋服务中心
B4: 所属期起 | C4: =IF(资产负债表!C4="","",资产负债表!C4) | F4: 所属期止 | G4: =IF(资产负债表!G4="","",资产负债表!G4)
B5: 项目 | C5: 行次 | D5: 本月数 | G5: 本年累计数
D6: 非限定性 | E6: 限定性 | F6: 合计 | G6: 非限定性 | H6: 限定性 | I6: 合计
B7: 一、收入
B8: 其中：捐赠收入 | C8: 1 | D8: 0 | E8: 0 | F8: =ROUND(业务活动表!D8+业务活动表!E8,2) -> 0 | G8: 0 | H8: 0 | I8: =ROUND(业务活动表!G8+业务活动表!H8,2) -> 0
B9: 会费收入 | C9: 2 | D9: 0 | E9: 0 | F9: =ROUND(业务活动表!D9+业务活动表!E9,2) -> 0 | G9: 0 | H9: 0 | I9: =ROUND(业务活动表!G9+业务活动表!H9,2) -> 0
B10: 提供服务收入 | C10: 3 | D10: 0 | E10: 0 | F10: =ROUND(业务活动表!D10+业务活动表!E10,2) -> 0 | G10: 0 | H10: 0 | I10: =ROUND(业务活动表!G10+业务活动表!H10,2) -> 0
B11: 商品销售收入 | C11: 4 | D11: 0 | E11: 0 | F11: =ROUND(业务活动表!D11+业务活动表!E11,2) -> 0 | G11: 0 | H11: 0 | I11: =ROUND(业务活动表!G11+业务活动表!H11,2) -> 0
B12: 政府补助收入 | C12: 5 | D12: 0 | E12: 0 | F12: =ROUND(业务活动表!D12+业务活动表!E12,2) -> 0 | G12: 0 | H12: 0 | I12: =ROUND(业务活动表!G12+业务活动表!H12,2) -> 0
B13: 投资收益 | C13: 6 | D13: 0 | E13: 0 | F13: =ROUND(业务活动表!D13+业务活动表!E13,2) -> 0 | G13: 0 | H13: 0 | I13: =ROUND(业务活动表!G13+业务活动表!H13,2) -> 0
B14: 其他收入 | C14: 9 | D14: 0 | E14: 0 | F14: =ROUND(业务活动表!D14+业务活动表!E14,2) -> 0 | G14: 0 | H14: 0 | I14: =ROUND(业务活动表!G14+业务活动表!H14,2) -> 0
B15: 收入合计 | C15: 11 | D15: =ROUND((D8+D9+D10+D11+D12+D13+D14),2) -> 0 | E15: =ROUND((E8+E9+E10+E11+E12+E13+E14),2) -> 0 | F15: =ROUND((F8+F9+F10+F11+F12+F13+F14),2) -> 0 | G15: =ROUND((G8+G9+G10+G11+G12+G13+G14),2) -> 0 | H15: =ROUND((H8+H9+H10+H11+H12+H13+H14),2) -> 0 | I15: =ROUND((I8+I9+I10+I11+I12+I13+I14),2) -> 0
B16: 二、费用
B17: （一）业务活动成本 | C17: 12 | D17: 0 | E17: 0 | F17: =ROUND(业务活动表!D17+业务活动表!E17,2) -> 0 | G17: 0 | H17: 0 | I17: =ROUND(业务活动表!G17+业务活动表!H17,2) -> 0
B18: 其中： | C18: 13 | D18: 0 | E18: 0 | F18: =ROUND(业务活动表!D18+业务活动表!E18,2) -> 0 | G18: 0 | H18: 0 | I18: =ROUND(业务活动表!G18+业务活动表!H18,2) -> 0
C19: 14 | D19: 0 | E19: 0 | F19: =ROUND(业务活动表!D19+业务活动表!E19,2) -> 0 | G19: 0 | H19: 0 | I19: =ROUND(业务活动表!G19+业务活动表!H19,2) -> 0
C20: 15 | D20: 0 | E20: 0 | F20: =ROUND(业务活动表!D20+业务活动表!E20,2) -> 0 | G20: 0 | H20: 0 | I20: =ROUND(业务活动表!G20+业务活动表!H20,2) -> 0
C21: 16 | D21: 0 | E21: 0 | F21: =ROUND(业务活动表!D21+业务活动表!E21,2) -> 0 | G21: 0 | H21: 0 | I21: =ROUND(业务活动表!G21+业务活动表!H21,2) -> 0
B22: （二）管理费用 | C22: 21 | D22: 0 | E22: 0 | F22: =ROUND(业务活动表!D22+业务活动表!E22,2) -> 0 | G22: 0 | H22: 0 | I22: =ROUND(业务活动表!G22+业务活动表!H22,2) -> 0
B23: （三）筹资费用 | C23: 24 | D23: 0 | E23: 0 | F23: =ROUND(业务活动表!D23+业务活动表!E23,2) -> 0 | G23: 0 | H23: 0 | I23: =ROUND(业务活动表!G23+业务活动表!H23,2) -> 0
B24: （四）其他费用 | C24: 28 | D24: 0 | E24: 0 | F24: =ROUND(业务活动表!D24+业务活动表!E24,2) -> 0 | G24: 0 | H24: 0 | I24: =ROUND(业务活动表!G24+业务活动表!H24,2) -> 0
B25: 费用合计 | C25: 35 | D25: =ROUND(业务活动表!D17+业务活动表!D22+业务活动表!D23+业务活动表!D24,2) -> 0 | E25: =ROUND(业务活动表!E17+业务活动表!E22+业务活动表!E23+业务活动表!E24,2) -> 0 | F25: =ROUND(业务活动表!F17+业务活动表!F22+业务活动表!F23+业务活动表!F24,2) -> 0 | G25: =ROUND(业务活动表!G17+业务活动表!G22+业务活动表!G23+业务活动表!G24,2) -> 0 | H25: =ROUND(业务活动表!H17+业务活动表!H22+业务活动表!H23+业务活动表!H24,2) -> 0 | I25: =ROUND(业务活动表!I17+业务活动表!I22+业务活动表!I23+业务活动表!I24,2) -> 0
B26: 三、限定性净资产转为非限定性净资产 | C26: 40 | D26: 0 | E26: 0 | F26: =ROUND(业务活动表!D26+业务活动表!E26,2) -> 0 | G26: 0 | H26: 0 | I26: =ROUND(业务活动表!G26+业务活动表!H26,2) -> 0
B27: 四、净资产变动额（若为净资产减少额，以“-”号填列） | C27: 45 | D27: =ROUND(业务活动表!D15-业务活动表!D25+业务活动表!D26,2) -> 0 | E27: =ROUND(业务活动表!E15-业务活动表!E25+业务活动表!E26,2) -> 0 | F27: =ROUND(业务活动表!D27+业务活动表!E27,2) -> 0 | G27: =ROUND(业务活动表!G15-业务活动表!G25+业务活动表!G26,2) -> 0 | H27: =ROUND(业务活动表!H15-业务活动表!H25+业务活动表!H26,2) -> 0 | I27: =ROUND(业务活动表!G27+业务活动表!H27,2) -> 0

Sheet 现金流量表
B1: 现金流量表（适用执行民间非营利组织会计制度的组织）
E2: 会民非03表 单位:元
B3: 纳税人识别号 | C3: =IF(资产负债表!C3="","",资产负债表!C3) -> 52310106MJ50512445
B4: 纳税人名称 | C4: =IF(资产负债表!G3="","",资产负债表!G3) -> 上海静安千千结婚恋服务中心
B5: 所属期起 | C5: =IF(资产负债表!C4="","",资产负债表!C4) | D5: 所属期止 | E5: =IF(资产负债表!G4="","",资产负债表!G4)
B6: 项目 | D6: 行次 | E6: 金 额
B7: 一、业务活动产生的现金流量：
B8: 接受捐赠收到的现金 | D8: 1 | E8: 0
B9: 收取会费收到的现金 | D9: 2 | E9: 0
B10: 提供服务收到的现金 | D10: 3 | E10: 0
B11: 销售商品收到的现金 | D11: 4 | E11: 0
B12: 政府补助收到的现金 | D12: 5 | E12: 0
B13: 收到的其他与业务活动有关的现金 | D13: 8 | E13: 0
B14: 现金流入小计 | D14: 13 | E14: =ROUND((E8+E9+E10+E11+E12+E13),2) -> 0
B15: 提供捐赠或者资助支付的现金 | D15: 14 | E15: 0
B16: 支付给员工以及为员工支付的现金 | D16: 15 | E16: 0
B17: 购买商品、接受服务支付的现金 | D17: 16 | E17: 0
B18: 支付的其他与业务活动有关的现金 | D18: 19 | E18: 0
B19: 现金流出小计 | D19: 23 | E19: =ROUND((E15+E16+E17+E18),2) -> 0
B20: 业务活动产生的现金流量净额 | D20: 24 | E20: =ROUND(现金流量表!E14-现金流量表!E19,2) -> 0
B21: 二、投资活动产生的现金流量：
B22: 收回投资所收到的现金 | D22: 25 | E22: 0
B23: 取得投资收益所收到的现金 | D23: 26 | E23: 0
B24: 处置固定资产和无形资产所收回的现金 | D24: 27 | E24: 0
B25: 收到的其他与投资活动有关的现金 | D25: 30 | E25: 0
B26: 现金流入小计 | D26: 34 | E26: =ROUND((E22+E23+E24+E25),2) -> 0
B27: 购建固定资产和无形资产所支付的现金 | D27: 35 | E27: 0
B28: 对外投资所支付的现金 | D28: 36 | E28: 0
B29: 支付的其他与投资活动有关的现金 | D29: 39 | E29: 0
B30: 现金流出小计 | D30: 43 | E30: =ROUND((E27+E28+E29),2) -> 0
B31: 投资活动产生的现金流量净额 | D31: 44 | E31: =ROUND(现金流量表!E26-现金流量表!E30,2) -> 0
B32: 三、筹资活动产生的现金流量：
B33: 借款所收到的现金 | D33: 45 | E33: 0
B34: 收到的其他与筹资活动有关的现金 | D34: 48 | E34: 0
B35: 现金流入小计 | D35: 50 | E35: =ROUND((E33+E34),2) -> 0
B36: 偿还借款所支付的现金 | D36: 51 | E36: 0
B37: 偿付利息所支付的现金 | D37: 52 | E37: 0
B38: 支付的其他与筹资活动有关的现金 | D38: 55 | E38: 0
B39: 现金流出小计 | D39: 58 | E39: =ROUND((E36+E37+E38),2) -> 0
B40: 筹资活动产生的现金流量净额 | D40: 59 | E40: =ROUND(现金流量表!E35-现金流量表!E39,2) -> 0
...
